Workbook

Sheet Panduan
B2: Panduan isi Satu Data Tambora
B3: Dashboard membaca tab Pengaturan, Tema, dan Item dari spreadsheet ini setiap kali dibuka. Ubah isinya di sini lalu muat ulang dashboard; kode tidak perlu diubah. Tab Panduan ini tidak dibaca dashboard.
B5: Yang boleh diubah
B6: Bagian | C6: Keterangan
B7: Baris 2 ke bawah | C7: Semua sel di bawah baris judul kolom pada tab Pengaturan, Tema, dan Item. Tambah baris baru di bawah baris terakhir.
B8: Baris 1 | C8: Judul kolom. Jangan ganti namanya, dan jangan ganti nama tab, karena dashboard mencarinya dengan nama itu.
B9: Kolom oranye | C9: Wajib diisi. Kolom abu-abu gelap boleh kosong.
B10: Catatan kolom | C10: Arahkan kursor ke judul kolom untuk melihat penjelasan singkatnya.
B12: Pekerjaan yang sering dilakukan
B13: Ingin | C13: Caranya
B14: Menambah isi | C14: Tab Item: tambah baris, isi tema (pilih dari daftar), judul, dan url. Kolom lain boleh kosong.
B15: Menyembunyikan | C15: Tulis tidak di kolom tampil. Baris tidak perlu dihapus.
B16: Mengganti isi utama | C16: Di tab Item, pindahkan ya pada kolom utama ke isi lain dalam tema yang sama.
B17: Menambah tema | C17: Tab Tema: tambah baris dengan id singkat tanpa spasi (contoh penyuluhan) dan judul. Lalu pakai id itu di kolom tema tab Item.
B18: Mengganti foto tema | C18: Kolom gambar di tab Tema: tempel link file gambar Google Drive yang dibagikan ke siapa saja yang memiliki link. Atur kolom fokus bila potongan foto kurang pas.
B20: Jenis isi (kolom jenis di tab Item)
B21: jenis | C21: Untuk | D21: Dibuka
B22: aplikasi | C22: Aplikasi web, misalnya dashboard di GitHub Pages | D22: di dalam dashboard
B23: peta | C23: Google My Maps atau WebGIS | D23: di dalam dashboard
B24: grafik | C24: Grafik terbitan Google Sheets (Publikasikan ke web) | D24: di dalam dashboard
B25: presentasi | C25: Google Slides | D25: di dalam dashboard
B26: data | C26: Google Sheets atau tabel | D26: di dalam dashboard (pratinjau)
B27: dokumen | C27: PDF atau Google Docs di Drive | D27: di dalam dashboard (pratinjau)
B28: folder | C28: Folder Google Drive | D28: di dalam dashboard
B29: tautan | C29: Situs lain | D29: di tab baru
B30: Link github.com selalu dibuka di tab baru. File Google yang tidak dibagikan ke publik hanya tampil bagi akun yang punya akses; tombol Buka di tab baru selalu tersedia.
B32: Kunci di tab Pengaturan
B33: kunci | C33: Isinya | D33: Tampil di
B34: judul | C34: Nama dashboard | D34: judul beranda dan tab browser
B35: subjudul | C35: Nama instansi | D35: di atas judul beranda dan di kaki halaman
B36: sambutan | C36: Satu kalimat pembuka | D36: beranda
B37: pengelola | C37: Pengelola dashboard | D37: kaki halaman
B38: github | C38: Repo kode dashboard (pemilik/nama-repo) | D38: tautan Kode di GitHub
B39: gambar_beranda | C39: Kosong = panorama Tambora bawaan, atau link gambar | D39: latar beranda
B41: Angka langsung
B42: Tema dengan id rbm, smart, karhut, dan resor menampilkan angka terkini dari Dashboard Capaian RBM, Dashboard SMART Patrol, Simulasi API Tambora, dan analisis Resor Pengelolaan. Jangan ganti keempat id itu; judul, foto, dan isinya boleh diubah.
B44: Ringkasan (dihitung otomatis)
B45: id | C45: Tema | D45: Isi yang tampil
B46: =IF(Tema!$A2="","",Tema!$A2) -> kawasan | C46: =IF(Tema!$A2="","",Tema!$B2) -> Profil Kawasan | D46: =IF(Tema!$A2="","",COUNTIFS(Item!$A$2:$A$400,Tema!$A2,Item!$J$2:$J$400,"<>tidak",Item!$C$2:$C$400,"<>")) -> 12
B47: =IF(Tema!$A3="","",Tema!$A3) -> resor | C47: =IF(Tema!$A3="","",Tema!$B3) -> Resor Pengelolaan | D47: =IF(Tema!$A3="","",COUNTIFS(Item!$A$2:$A$400,Tema!$A3,Item!$J$2:$J$400,"<>tidak",Item!$C$2:$C$400,"<>")) -> 9
...

Sheet Pengaturan
A1: kunci | B1: nilai
A2: judul | B2: Satu Data Tambora
A3: subjudul | B3: Balai Taman Nasional Tambora
A4: sambutan | B4: Data kawasan, patroli, resor, kebakaran hutan, perlindungan, dan wisata Taman Nasional Tambora dalam satu layar.
A5: pengelola | B5: Dikelola oleh Pokja Urusan Advokasi Hukum, Bahan Pemanfaatan, Pelayanan, Perlindungan, Pengamanan dan Pengawetan Balai Taman Nasional Tambora Tahun 2026
A6: github | B6: kopluck8/Satu-Data-Tambora
A7: gambar_beranda

Sheet Tema
A1: id | B1: judul | C1: label | D1: ringkas | E1: ikon | F1: warna | G1: gambar | H1: fokus | I1: kredit | J1: sorotan | K1: tampil
A2: kawasan | B2: Profil Kawasan | C2: Taman Nasional Tambora | D2: Data dasar kawasan: dokumen kawasan, kondisi fisik dan geomorfologi, keanekaragaman hayati, aksesibilitas, dan desa binaan. | E2: gunung | F2: #6cc4ff | G2: assets/foto/kawasan.jpg | H2: 50% 45% | J2: Letusan 1815; Salah satu kaldera terdalam di dunia; Satwa kunci Elang Flores dan Rusa Timor | K2: ya
A3: resor | B3: Resor Pengelolaan | C3: Tujuh resor hasil kajian 2026 | D3: Profil potensi dan ancaman setiap resor pengelolaan: batas resor 2026, penilaian ancaman Miradi, temuan SMART Patrol, beban kerja, dan kebutuhan personel. | E3: pohon | F3: #52c97c | J3: 7 resor di 2 SPTN; Resor baru Doro Tabe; Potensi dan ancaman tiap resor | K3: ya
A4: smart | B4: SMART Patrol | C4: Spatial Monitoring and Reporting Tool | D4: Temuan patroli dari seluruh resor: statistik, grafik per kategori, peta sebaran, pembuat laporan patroli, dan data patroli drone. | E4: patroli | F4: #a5d66f | G4: assets/foto/smart.jpg | H4: 56% 45% | I4: Foto: Dok. TN Tambora | J4: 9 kategori temuan; Rekap per SPTN dan resor; LPK dan RPK otomatis | K4: ya
A5: rbm | B5: Resort Based Management | C5: Pengelolaan berbasis resor | D5: Laporan kegiatan resor dan capaiannya terhadap rencana 2026, dihitung langsung dari laporan yang sudah diverifikasi. | E5: resor | F5: #ffcf6e | G5: assets/foto/rbm.jpg | H5: 50% 60% | I5: Foto: SPTN Wilayah II | J5: 6 resor di 2 SPTN; 100 kegiatan dalam rencana 2026; Lapor tanpa akun | K5: ya
A6: karhut | B6: Kebakaran Hutan | C6: Pengendalian kebakaran hutan | D6: Hotspot harian, delineasi areal terbakar tiap 5 hari, peta kerawanan, rekap kejadian, dan pemodelan rambatan api. | E6: api | F6: #ff8a4c | G6: assets/foto/karhut.jpg | H6: 62% 50% | J6: Hotspot MODIS dan VIIRS; Delineasi areal terbakar tiap 5 hari; Simulasi rambatan api | K6: ya
A7: polhut | B7: Perlindungan Kawasan | C7: Polisi Kehutanan | D7: Laporan kejadian, database Polisi Kehutanan, dan sebaran gangguan kawasan sejak 2020. | E7: perisai | F7: #d2bc84 | G7: assets/foto/polhut.jpg | H7: 58% 50% | J7: Rekap laporan kejadian 2026; Database Polhut; Sebaran gangguan 2020–2026 | K7: ya
A8: wisata | B8: Wisata & Pelayanan | C8: Wisata alam dan pendakian | D8: Kunjungan wisata dan pendakian: pengunjung nusantara dan mancanegara, asal pendaki, Oi Marai, dan Sanctuary Rusa Timor. | E8: wisata | F8: #4fd6c7 | G8: assets/foto/wisata.jpg | H8: 72% 50% | I8: Foto: Dwi Oblo | J8: Pendakian Gunung Tambora; Oi Marai; Sanctuary Rusa Timor | K8: ya
A9: bmn | B9: Aset BMN | C9: Barang Milik Negara | D9: Baca file Daftar Aset BMN langsung di browser untuk ringkasan, temuan yang perlu ditindaklanjuti, dan unduhan CSV. | E9: aset | F9: #a99bff | J9: File dibaca di browser, tidak diunggah; Kandidat penghapusan; Kendaraan dan umur aset | K9: ya

Sheet Item
A1: tema | B1: kelompok | C1: judul | D1: jenis | E1: url | F1: keterangan | G1: gambar | H1: repo | I1: utama | J1: tampil
A2: kawasan | B2: Dokumen kawasan | C2: Pustaka Data Dasar Kawasan | D2: folder | E2: https://drive.google.com/drive/folders/1ZmpztD8BdgLzmGVOKWTois-_74JTYmE8 | F2: Folder Google Drive berisi dokumen dan data dasar kawasan. | I2: ya | J2: ya
A3: kawasan | B3: Dokumen kawasan | C3: SK Dirjen KSDAE Nomor 138 Tahun 2025 | D3: dokumen | E3: https://drive.google.com/file/d/1ZlCfyWf7CsY2PKB4PnQwUDqA5Q--oii5/view | F3: Salinan surat keputusan di Google Drive. | J3: ya
A4: kawasan | B4: Dokumen kawasan | C4: Sejarah Kawasan | D4: presentasi | E4: https://docs.google.com/presentation/d/1dMAojMH3mYI1xGQ7XJYUghzzV1H9KzbWDHc9oKnlSt0/present | F4: Presentasi sejarah kawasan Tambora. | J4: ya
A5: kawasan | B5: Fisik dan geomorfologi | C5: Kondisi Fisik Kawasan | D5: presentasi | E5: https://docs.google.com/presentation/d/1cbdvAvSIiXViCcLJTarK0AdAgw2oeux728IyLzdX2X8/present | F5: Kondisi fisik kawasan yang terus berubah sejak letusan 1815. | J5: ya
A6: kawasan | B6: Fisik dan geomorfologi | C6: Geogenesis Gunung Tambora | D6: presentasi | E6: https://docs.google.com/presentation/d/1cQkQEU9sCjMPtNgu82hV_oAa1HhQlkhv47-YsVZsIPs/present | F6: Asal-usul dan pembentukan Gunung Tambora. | J6: ya
A7: kawasan | B7: Fisik dan geomorfologi | C7: Geomorfologi Kawasan | D7: presentasi | E7: https://docs.google.com/presentation/d/1doeg08LdjkoSmUTRhUdggSgSo6014w6jRe9E0OfP1fo/present | F7: Bentuk lahan kawasan Tambora. | J7: ya
A8: kawasan | B8: Keanekaragaman hayati | C8: Daftar Jenis Terverifikasi | D8: data | E8: https://docs.google.com/spreadsheets/d/1g31M2KhRn0MeJ6skbQ69bUQue6qqqF7BPDfwI7LOuKM/edit | F8: Rincian daftar jenis yang sudah diverifikasi. | G8: assets/foto/lebah.jpg | J8: ya
A9: kawasan | B9: Keanekaragaman hayati | C9: Sebaran per Jenis | D9: data | E9: https://docs.google.com/spreadsheets/d/1zF6lLubW2I2HJbHNxqhksAO-3EsmSumNAy6gPJCJn5Y/edit | F9: Rincian data sebaran setiap jenis. | J9: ya
A10: kawasan | B10: Keanekaragaman hayati | C10: Distribusi Habitat Satwa Liar | D10: presentasi | E10: https://docs.google.com/presentation/d/1e_tEflWde51eCdi9MQPxABDquUlvfnxlGYS4LwfgTJk/present | F10: Sebaran habitat satwa liar di kawasan. | J10: ya
A11: kawasan | B11: Keanekaragaman hayati | C11: Distribusi Tumbuhan | D11: presentasi | E11: https://docs.google.com/presentation/d/1QW7CkPYxAhe1WH8MABLuK4KsAoe-3AgxQiWERzl4dE0/present | F11: Sebaran jenis tumbuhan di kawasan. | J11: ya
A12: kawasan | B12: Akses dan desa | C12: Aksesibilitas ke Dalam Kawasan | D12: peta | E12: https://www.google.com/maps/d/embed?mid=1TzuDicUDgnkB1cy1VjPuoYjQxUvj4rA | F12: Peta jalur dan akses masuk kawasan. | J12: ya
A13: kawasan | B13: Akses dan desa | C13: Desa Binaan | D13: peta | E13: https://www.google.com/maps/d/embed?mid=1QpvKZnaRnsVIzZ3g_YUobbG9jCkICPg | F13: Peta desa binaan di sekitar kawasan. | J13: ya
A14: resor | B14: Ikhtisar | C14: Profil Tujuh Resor Pengelolaan | D14: aplikasi | E14: resor/index.html#/ | F14: Peta batas resor 2026, peringkat ancaman dan potensi tiap resor, beban kerja, dan perubahan batas dari 6 menjadi 7 resor. | H14: kopluck8/Satu-Data-Tambora | I14: ya | J14: ya
A15: resor | B15: Ikhtisar | C15: Metode Penilaian Potensi dan Ancaman | D15: dokumen | E15: resor/index.html#/metode | F15: Penilaian ancaman Miradi (Conservation Standards), laju temuan SMART per 10 hari patroli, dan tiga fungsi kawasan konservasi. | H15: kopluck8/Satu-Data-Tambora | J15: ya
A16: resor | B16: SPTN Wilayah I Kore | C16: Resor Piong | D16: aplikasi | E16: resor/index.html#/piong | F16: Savana, pendakian berkendara, dan habitat Rusa timor. Desa binaan Piong dan Oi Saro. | H16: kopluck8/Satu-Data-Tambora | J16: ya
A17: resor | B17: SPTN Wilayah I Kore | C17: Resor Oi Katupa | D17: aplikasi | E17: resor/index.html#/oi-katupa | F17: Habitat Elang flores dan Rusa timor, madu hutan, dan sumber air. Desa binaan Oi Katupa, Kawinda Toi, dan Piong. | H17: kopluck8/Satu-Data-Tambora | J17: ya
A18: resor | B18: SPTN Wilayah I Kore | C18: Resor Kawinda Toi | D18: aplikasi | E18: resor/index.html#/kawinda-toi | F18: Wisata pendakian dan Air Terjun Oi Marai, madu hutan, dan sumber air. Desa binaan Kawinda Toi dan Kawinda Nae. | H18: kopluck8/Satu-Data-Tambora | J18: ya
A19: resor | B19: SPTN Wilayah II Pekat | C19: Resor Doro Tabe (baru) | D19: aplikasi | E19: resor/index.html#/doro-tabe | F19: Resor baru 2026 dari pemekaran Doroncanga: savana dan fitur geologi. Desa binaan Tolokalo dan Soritatanga. | H19: kopluck8/Satu-Data-Tambora | J19: ya
A20: resor | B20: SPTN Wilayah II Pekat | C20: Resor Doroncanga | D20: aplikasi | E20: resor/index.html#/doroncanga | F20: Sanctuary Rusa Timor, savana, dan jalur pendakian berkendara. Desa binaan Soritatanga. | H20: kopluck8/Satu-Data-Tambora | J20: ya
A21: resor | B21: SPTN Wilayah II Pekat | C21: Resor Doropeti | D21: aplikasi | E21: resor/index.html#/doropeti | F21: Areal bernilai konservasi tinggi, habitat Elang flores, dan sumber air. Desa binaan Doropeti dan Soritatanga. | H21: kopluck8/Satu-Data-Tambora | J21: ya
A22: resor | B22: SPTN Wilayah II Pekat | C22: Resor Pancasila | D22: aplikasi | E22: resor/index.html#/pancasila | F22: Jalur pendakian ke puncak Tambora dan habitat Rusa timor. Desa binaan Tambora dan Kawinda Nae. | H22: kopluck8/Satu-Data-Tambora | J22: ya
A23: smart | B23: Aplikasi | C23: Dashboard Data SMART Patrol | D23: aplikasi | E23: https://kopluck8.github.io/Dashboard_SMART_TNGunungTambora/ | F23: Statistik, grafik, peta, dan tabel temuan patroli per kategori, SPTN, dan resor. | H23: kopluck8/Dashboard_SMART_TNGunungTambora | I23: ya | J23: ya
A24: smart | B24: Aplikasi | C24: Generator LPK & RPK | D24: aplikasi | E24: https://kopluck8.github.io/SMART_Report_generator/ | F24: Mengubah ekspor SMART Desktop menjadi Laporan Pelaksanaan Kegiatan dan menyusun Rencana Pelaksanaan Kegiatan. | H24: kopluck8/SMART_Report_generator | J24: ya
A25: smart | B25: Aplikasi | C25: Flight SMART | D25: aplikasi | E25: https://kopluck8.github.io/Flight_SMART/ | F25: Arsip log terbang drone DJI (jalur GPX, KML, peta) dan pengisian data SMART untuk foto drone. | H25: kopluck8/Flight_SMART | J25: ya
A26: smart | B26: Rekap per kategori | C26: Aktivitas Manusia | D26: grafik | E26: https://kopluck8.github.io/Dashboard_SMART_TNGunungTambora/aktivitas-manusia.html?embed=1 | F26: Temuan aktivitas manusia: komposisi, tren bulanan, peta, dan rincian. | J26: ya
A27: smart | B27: Rekap per kategori | C27: Satwa Liar | D27: grafik | E27: https://kopluck8.github.io/Dashboard_SMART_TNGunungTambora/satwa-liar.html?embed=1 | F27: Daftar jenis satwa, tren bulanan, dan peta sebaran temuan. | J27: ya
A28: smart | B28: Rekap per kategori | C28: Tumbuhan | D28: grafik | E28: https://kopluck8.github.io/Dashboard_SMART_TNGunungTambora/tumbuhan.html?embed=1 | F28: Daftar jenis tumbuhan, tren bulanan, dan peta sebaran temuan. | J28: ya
A29: smart | B29: Rekap per kategori | C29: Spesies Invasif | D29: grafik | E29: https://kopluck8.github.io/Dashboard_SMART_TNGunungTambora/spesies-invasif.html?embed=1 | F29: Temuan spesies invasif: komposisi, tren bulanan, dan peta. | J29: ya
A30: smart | B30: Rekap per kategori | C30: Fitur | D30: grafik | E30: https://kopluck8.github.io/Dashboard_SMART_TNGunungTambora/fitur.html?embed=1 | F30: Temuan fitur kawasan: komposisi, tren bulanan, dan peta. | J30: ya
A31: smart | B31: Rekap per kategori | C31: Ground Check | D31: grafik | E31: https://kopluck8.github.io/Dashboard_SMART_TNGunungTambora/ground-check.html?embed=1 | F31: Ground check tipe ekosistem dan tutupan lahan. | J31: ya
A32: smart | B32: Rekap per kategori | C32: Pengelolaan | D32: grafik | E32: https://kopluck8.github.io/Dashboard_SMART_TNGunungTambora/pengelolaan.html?embed=1 | F32: Temuan kegiatan pengelolaan: komposisi, tren bulanan, dan peta. | J32: ya
A33: smart | B33: Rekap per kategori | C33: Penyuluhan dan Pemberdayaan Masyarakat | D33: grafik | E33: https://kopluck8.github.io/Dashboard_SMART_TNGunungTambora/penyuluhan.html?embed=1 | F33: Kegiatan penyuluhan dan pemberdayaan masyarakat. | J33: ya
A34: smart | B34: Rekap per kategori | C34: Jalur Pendakian dan ODTWA | D34: grafik | E34: https://kopluck8.github.io/Dashboard_SMART_TNGunungTambora/jalur-pendakian.html?embed=1 | F34: Penjagaan jalur pendakian dan objek daya tarik wisata alam. | J34: ya
A35: smart | B35: Peta dan rekap | C35: Peta Temuan SMART Patrol | D35: peta | E35: https://www.google.com/maps/d/embed?mid=1zzggN4lmKULtMFTWs6ofxUdfCKZDaFg | F35: Peta Google My Maps berisi titik temuan patroli. | J35: ya
A36: smart | B36: Peta dan rekap | C36: Rekap SMART 2026 | D36: data | E36: https://drive.google.com/open?id=1VfP1gZb7Ah9Lt0iNAjVvUGbjVN19aZ2b-7XXfjnUNK8 | F36: Tabulasi data SMART Patrol tahun 2026. | J36: ya
A37: rbm | B37: Aplikasi | C37: Dashboard Capaian RBM 2026 | D37: aplikasi | E37: https://kopluck8.github.io/RBM_TNGunungTambora/dashboard/ | F37: Capaian terverifikasi setiap resor dibandingkan rencana awal tahun. | H37: kopluck8/RBM_TNGunungTambora | I37: ya | J37: ya
A38: rbm | B38: Aplikasi | C38: Form Laporan Kegiatan | D38: aplikasi | E38: https://kopluck8.github.io/RBM_TNGunungTambora/form/ | F38: Petugas resor melaporkan kegiatan lewat form web tanpa perlu akun. | H38: kopluck8/RBM_TNGunungTambora | J38: ya
A39: rbm | B39: Aplikasi | C39: Laporan Bulanan RBM | D39: aplikasi | E39: https://kopluck8.github.io/RBM_TNGunungTambora/laporan/ | F39: Resor mengunduh PDF laporan bulanan dengan kode akses. | H39: kopluck8/RBM_TNGunungTambora | J39: ya
A40: rbm | B40: Grafik | C40: Beban Kerja TN Tambora | D40: grafik | E40: https://docs.google.com/spreadsheets/d/e/2CAIWO3emAV1x3glDUfwxF17DdMTFQ3Ir6qmjgL00uSfi205SDI1PS6XoWdV2LVBmWB5XiQoFZzOv80BSqRQ/gviz/chartiframe?autosize=true&oid=930395445 | F40: Grafik beban kerja Balai TN Tambora. | J40: ya
...
